Workbook
Name Slicer_Diabetes_Status: #N/A
Name Slicer_Weight_Status: #N/A

Sheet Customer Names
A1: Customer ID | B1: name | C1: Title | D1: First Name | E1: Last Name
A2: Id1 | B2: Hawks, Ms. Kelly | C2: =MID(B2,FIND(",",B2)+2,FIND(" ",B2,FIND(",",B2)+2)-FIND(",",B2)-2) -> Ms. | D2: =MID(B2,FIND(" ",B2,FIND(",",B2)+2)+1,LEN(B2)-FIND(" ",B2,FIND(",",B2)+2)) -> Kelly | E2: =LEFT(B2,FIND(",",B2)-1) -> Hawks
A3: Id2 | B3: Lehner, Mr. Matthew D | C3: =MID(B3,FIND(",",B3)+2,FIND(" ",B3,FIND(",",B3)+2)-FIND(",",B3)-2) -> Mr. | D3: =MID(B3,FIND(" ",B3,FIND(",",B3)+2)+1,LEN(B3)-FIND(" ",B3,FIND(",",B3)+2)) -> Matthew D | E3: =LEFT(B3,FIND(",",B3)-1) -> Lehner
A4: Id3 | B4: Lu, Mr. Phil | C4: =MID(B4,FIND(",",B4)+2,FIND(" ",B4,FIND(",",B4)+2)-FIND(",",B4)-2) -> Mr. | D4: =MID(B4,FIND(" ",B4,FIND(",",B4)+2)+1,LEN(B4)-FIND(" ",B4,FIND(",",B4)+2)) -> Phil | E4: =LEFT(B4,FIND(",",B4)-1) -> Lu
A5: Id4 | B5: Osborne, Ms. Kelsey | C5: =MID(B5,FIND(",",B5)+2,FIND(" ",B5,FIND(",",B5)+2)-FIND(",",B5)-2) -> Ms. | D5: =MID(B5,FIND(" ",B5,FIND(",",B5)+2)+1,LEN(B5)-FIND(" ",B5,FIND(",",B5)+2)) -> Kelsey | E5: =LEFT(B5,FIND(",",B5)-1) -> Osborne
A6: Id5 | B6: Kadala, Ms. Kristyn | C6: =MID(B6,FIND(",",B6)+2,FIND(" ",B6,FIND(",",B6)+2)-FIND(",",B6)-2) -> Ms. | D6: =MID(B6,FIND(" ",B6,FIND(",",B6)+2)+1,LEN(B6)-FIND(" ",B6,FIND(",",B6)+2)) -> Kristyn | E6: =LEFT(B6,FIND(",",B6)-1) -> Kadala
A7: Id6 | B7: Baker, Mr. Russell B. | C7: =MID(B7,FIND(",",B7)+2,FIND(" ",B7,FIND(",",B7)+2)-FIND(",",B7)-2) -> Mr. | D7: =MID(B7,FIND(" ",B7,FIND(",",B7)+2)+1,LEN(B7)-FIND(" ",B7,FIND(",",B7)+2)) -> Russell B. | E7: =LEFT(B7,FIND(",",B7)-1) -> Baker
A8: Id7 | B8: Macpherson, Mr. Scott | C8: =MID(B8,FIND(",",B8)+2,FIND(" ",B8,FIND(",",B8)+2)-FIND(",",B8)-2) -> Mr. | D8: =MID(B8,FIND(" ",B8,FIND(",",B8)+2)+1,LEN(B8)-FIND(" ",B8,FIND(",",B8)+2)) -> Scott | E8: =LEFT(B8,FIND(",",B8)-1) -> Macpherson
A9: Id8 | B9: Hallman, Mr. Stephen | C9: =MID(B9,FIND(",",B9)+2,FIND(" ",B9,FIND(",",B9)+2)-FIND(",",B9)-2) -> Mr. | D9: =MID(B9,FIND(" ",B9,FIND(",",B9)+2)+1,LEN(B9)-FIND(" ",B9,FIND(",",B9)+2)) -> Stephen | E9: =LEFT(B9,FIND(",",B9)-1) -> Hallman
A10: Id9 | B10: Moran, Mr. Patrick R. | C10: =MID(B10,FIND(",",B10)+2,FIND(" ",B10,FIND(",",B10)+2)-FIND(",",B10)-2) -> Mr. | D10: =MID(B10,FIND(" ",B10,FIND(",",B10)+2)+1,LEN(B10)-FIND(" ",B10,FIND(",",B10)+2)) -> Patrick R. | E10: =LEFT(B10,FIND(",",B10)-1) -> Moran
A11: Id10 | B11: Benner, Ms. Brooke N. | C11: =MID(B11,FIND(",",B11)+2,FIND(" ",B11,FIND(",",B11)+2)-FIND(",",B11)-2) -> Ms. | D11: =MID(B11,FIND(" ",B11,FIND(",",B11)+2)+1,LEN(B11)-FIND(" ",B11,FIND(",",B11)+2)) -> Brooke N. | E11: =LEFT(B11,FIND(",",B11)-1) -> Benner
A12: Id11 | B12: Fierro Vargas, Ms. Paola Andrea | C12: =MID(B12,FIND(",",B12)+2,FIND(" ",B12,FIND(",",B12)+2)-FIND(",",B12)-2) -> Ms. | D12: =MID(B12,FIND(" ",B12,FIND(",",B12)+2)+1,LEN(B12)-FIND(" ",B12,FIND(",",B12)+2)) -> Paola Andrea | E12: =LEFT(B12,FIND(",",B12)-1) -> Fierro Vargas
A13: Id12 | B13: Franz, Mr. David | C13: =MID(B13,FIND(",",B13)+2,FIND(" ",B13,FIND(",",B13)+2)-FIND(",",B13)-2) -> Mr. | D13: =MID(B13,FIND(" ",B13,FIND(",",B13)+2)+1,LEN(B13)-FIND(" ",B13,FIND(",",B13)+2)) -> David | E13: =LEFT(B13,FIND(",",B13)-1) -> Franz
... A2336: Id2335 | B2336: German, Mr. Aaron K | C2336: =MID(B2336,FIND(",",B2336)+2,FIND(" ",B2336,FIND(",",B2336)+2)-FIND(",",B2336)-2) -> Mr. | D2336: =MID(B2336,FIND(" ",B2336,FIND(",",B2336)+2)+1,LEN(B2336)-FIND(" ",B2336,FIND(",",B2336)+2)) -> Aaron K | E2336: =LEFT(B2336,FIND(",",B2336)-1) -> German

Sheet Medical Examinations
A1: Customer ID | B1: BMI | C1: HBA1C | D1: Heart Issues | E1: Any Transplants | F1: Cancer history | G1: NumberOfMajorSurgeries | H1: smoker | I1: Number Of Major Surgeries (Cleaned) | J1: smoker (Cleaned) | K1: Heart Issues (Cleaned) | L1: Weight Status | M1: Diabetes Status
A2: Id1 | B2: 47.41 | C2: 7.47 | D2: No | E2: No | F2: No | G2: No major surgery | H2: yes | I2: =IF(G2="No major surgery",0,G2) -> 0 | J2: =PROPER(H2) -> Yes | K2: =PROPER(D2) -> No | L2: =IF(B2<18.5,"Underweight",IF(B2<25,"Normal Weight",IF(B2<30,"Overweight","Obesity"))) -> Obesity | M2: =IF(C2<5.7,"Normal",IF(C2<6.5,"Prediabetes","Diabetes")) -> Diabetes | O2: Data Cleaning Helper Calculations
A3: Id2 | B3: 30.36 | C3: 5.77 | D3: No | E3: No | F3: No | G3: No major surgery | H3: yes | I3: =IF(G3="No major surgery",0,G3) -> 0 | J3: =PROPER(H3) -> Yes | K3: =PROPER(D3) -> No | L3: =IF(B3<18.5,"Underweight",IF(B3<25,"Normal Weight",IF(B3<30,"Overweight","Obesity"))) -> Obesity | M3: =IF(C3<5.7,"Normal",IF(C3<6.5,"Prediabetes","Diabetes")) -> Prediabetes | O3: Mode (most frequent smoker value, for filling "?") | P3: 0
A4: Id3 | B4: 34.485 | C4: 11.87 | D4: yes | E4: No | F4: No | G4: 2 | H4: yes | I4: =IF(G4="No major surgery",0,G4) -> 2 | J4: =PROPER(H4) -> Yes | K4: =PROPER(D4) -> Yes | L4: =IF(B4<18.5,"Underweight",IF(B4<25,"Normal Weight",IF(B4<30,"Overweight","Obesity"))) -> Obesity | M4: =IF(C4<5.7,"Normal",IF(C4<6.5,"Prediabetes","Diabetes")) -> Diabetes
A5: Id4 | B5: 38.095 | C5: 6.05 | D5: No | E5: No | F5: No | G5: No major surgery | H5: yes | I5: =IF(G5="No major surgery",0,G5) -> 0 | J5: =PROPER(H5) -> Yes | K5: =PROPER(D5) -> No | L5: =IF(B5<18.5,"Underweight",IF(B5<25,"Normal Weight",IF(B5<30,"Overweight","Obesity"))) -> Obesity | M5: =IF(C5<5.7,"Normal",IF(C5<6.5,"Prediabetes","Diabetes")) -> Prediabetes
A6: Id5 | B6: 35.53 | C6: 5.45 | D6: No | E6: No | F6: No | G6: No major surgery | H6: yes | I6: =IF(G6="No major surgery",0,G6) -> 0 | J6: =PROPER(H6) -> Yes | K6: =PROPER(D6) -> No | L6: =IF(B6<18.5,"Underweight",IF(B6<25,"Normal Weight",IF(B6<30,"Overweight","Obesity"))) -> Obesity | M6: =IF(C6<5.7,"Normal",IF(C6<6.5,"Prediabetes","Diabetes")) -> Normal
A7: Id6 | B7: 32.8 | C7: 6.59 | D7: No | E7: No | F7: No | G7: No major surgery | H7: yes | I7: =IF(G7="No major surgery",0,G7) -> 0 | J7: =PROPER(H7) -> Yes | K7: =PROPER(D7) -> No | L7: =IF(B7<18.5,"Underweight",IF(B7<25,"Normal Weight",IF(B7<30,"Overweight","Obesity"))) -> Obesity | M7: =IF(C7<5.7,"Normal",IF(C7<6.5,"Prediabetes","Diabetes")) -> Diabetes
A8: Id7 | B8: 36.4 | C8: 6.07 | D8: No | E8: No | F8: No | G8: No major surgery | H8: yes | I8: =IF(G8="No major surgery",0,G8) -> 0 | J8: =PROPER(H8) -> Yes | K8: =PROPER(D8) -> No | L8: =IF(B8<18.5,"Underweight",IF(B8<25,"Normal Weight",IF(B8<30,"Overweight","Obesity"))) -> Obesity | M8: =IF(C8<5.7,"Normal",IF(C8<6.5,"Prediabetes","Diabetes")) -> Prediabetes
A9: Id8 | B9: 36.96 | C9: 7.93 | D9: No | E9: No | F9: No | G9: 3 | H9: yes | I9: =IF(G9="No major surgery",0,G9) -> 3 | J9: =PROPER(H9) -> Yes | K9: =PROPER(D9) -> No | L9: =IF(B9<18.5,"Underweight",IF(B9<25,"Normal Weight",IF(B9<30,"Overweight","Obesity"))) -> Obesity | M9: =IF(C9<5.7,"Normal",IF(C9<6.5,"Prediabetes","Diabetes")) -> Diabetes
A10: Id9 | B10: 41.14 | C10: 9.58 | D10: yes | E10: No | F10: Yes | G10: 1 | H10: yes | I10: =IF(G10="No major surgery",0,G10) -> 1 | J10: =PROPER(H10) -> Yes | K10: =PROPER(D10) -> Yes | L10: =IF(B10<18.5,"Underweight",IF(B10<25,"Normal Weight",IF(B10<30,"Overweight","Obesity"))) -> Obesity | M10: =IF(C10<5.7,"Normal",IF(C10<6.5,"Prediabetes","Diabetes")) -> Diabetes
A11: Id10 | B11: 38.06 | C11: 10.79 | D11: No | E11: No | F11: No | G11: No major surgery | H11: yes | I11: =IF(G11="No major surgery",0,G11) -> 0 | J11: =PROPER(H11) -> Yes | K11: =PROPER(D11) -> No | L11: =IF(B11<18.5,"Underweight",IF(B11<25,"Normal Weight",IF(B11<30,"Overweight","Obesity"))) -> Obesity | M11: =IF(C11<5.7,"Normal",IF(C11<6.5,"Prediabetes","Diabetes")) -> Diabetes
A12: Id11 | B12: 37.7 | C12: 5.96 | D12: yes | E12: No | F12: No | G12: 2 | H12: yes | I12: =IF(G12="No major surgery",0,G12) -> 2 | J12: =PROPER(H12) -> Yes | K12: =PROPER(D12) -> Yes | L12: =IF(B12<18.5,"Underweight",IF(B12<25,"Normal Weight",IF(B12<30,"Overweight","Obesity"))) -> Obesity | M12: =IF(C12<5.7,"Normal",IF(C12<6.5,"Prediabetes","Diabetes")) -> Prediabetes
A13: Id12 | B13: 42.13 | C13: 11.9 | D13: No | E13: No | F13: No | G13: No major surgery | H13: yes | I13: =IF(G13="No major surgery",0,G13) -> 0 | J13: =PROPER(H13) -> Yes | K13: =PROPER(D13) -> No | L13: =IF(B13<18.5,"Underweight",IF(B13<25,"Normal Weight",IF(B13<30,"Overweight","Obesity"))) -> Obesity | M13: =IF(C13<5.7,"Normal",IF(C13<6.5,"Prediabetes","Diabetes")) -> Diabetes
A14: Id13 | B14: 40.92 | C14: 8.41 | D14: No | E14: No | F14: No | G14: No major surgery | H14: yes | I14: =IF(G14="No major surgery",0,G14) -> 0 | J14: =PROPER(H14) -> Yes | K14: =PROPER(D14) -> No | L14: =IF(B14<18.5,"Underweight",IF(B14<25,"Normal Weight",IF(B14<30,"Overweight","Obesity"))) -> Obesity | M14: =IF(C14<5.7,"Normal",IF(C14<6.5,"Prediabetes","Diabetes")) -> Diabetes
A15: Id14 | B15: 40.565 | C15: 7.02 | D15: No | E15: No | F15: No | G15: No major surgery | H15: yes | I15: =IF(G15="No major surgery",0,G15) -> 0 | J15: =PROPER(H15) -> Yes | K15: =PROPER(D15) -> No | L15: =IF(B15<18.5,"Underweight",IF(B15<25,"Normal Weight",IF(B15<30,"Overweight","Obesity"))) -> Obesity | M15: =IF(C15<5.7,"Normal",IF(C15<6.5,"Prediabetes","Diabetes")) -> Diabetes
A16: Id15 | B16: 36.385 | C16: 7.59 | D16: yes | E16: No | F16: No | G16: 2 | H16: yes | I16: =IF(G16="No major surgery",0,G16) -> 2 | J16: =PROPER(H16) -> Yes | K16: =PROPER(D16) -> Yes | L16: =IF(B16<18.5,"Underweight",IF(B16<25,"Normal Weight",IF(B16<30,"Overweight","Obesity"))) -> Obesity | M16: =IF(C16<5.7,"Normal",IF(C16<6.5,"Prediabetes","Diabetes")) -> Diabetes
A17: Id16 | B17: 39.9 | C17: 11.32 | D17: No | E17: No | F17: No | G17: No major surgery | H17: yes | I17: =IF(G17="No major surgery",0,G17) -> 0 | J17: =PROPER(H17) -> Yes | K17: =PROPER(D17) -> No | L17: =IF(B17<18.5,"Underweight",IF(B17<25,"Normal Weight",IF(B17<30,"Overweight","Obesity"))) -> Obesity | M17: =IF(C17<5.7,"Normal",IF(C17<6.5,"Prediabetes","Diabetes")) -> Diabetes
A18: Id17 | B18: 33.8 | C18: 7.67 | D18: No | E18: No | F18: No | G18: 3 | H18: yes | I18: =IF(G18="No major surgery",0,G18) -> 3 | J18: =PROPER(H18) -> Yes | K18: =PROPER(D18) -> No | L18: =IF(B18<18.5,"Underweight",IF(B18<25,"Normal Weight",IF(B18<30,"Overweight","Obesity"))) -> Obesity | M18: =IF(C18<5.7,"Normal",IF(C18<6.5,"Prediabetes","Diabetes")) -> Diabetes
A19: Id18 | B19: 36.765 | C19: 7.29 | D19: yes | E19: No | F19: Yes | G19: 1 | H19: yes | I19: =IF(G19="No major surgery",0,G19) -> 1 | J19: =PROPER(H19) -> Yes | K19: =PROPER(D19) -> Yes | L19: =IF(B19<18.5,"Underweight",IF(B19<25,"Normal Weight",IF(B19<30,"Overweight","Obesity"))) -> Obesity | M19: =IF(C19<5.7,"Normal",IF(C19<6.5,"Prediabetes","Diabetes")) -> Diabetes
A20: Id19 | B20: 36.955 | C20: 4.72 | D20: yes | E20: No | F20: No | G20: 1 | H20: yes | I20: =IF(G20="No major surgery",0,G20) -> 1 | J20: =PROPER(H20) -> Yes | K20: =PROPER(D20) -> Yes | L20: =IF(B20<18.5,"Underweight",IF(B20<25,"Normal Weight",IF(B20<30,"Overweight","Obesity"))) -> Obesity | M20: =IF(C20<5.7,"Normal",IF(C20<6.5,"Prediabetes","Diabetes")) -> Normal
A21: Id20 | B21: 42.9 | C21: 11.41 | D21: No | E21: No | F21: No | G21: No major surgery | H21: yes | I21: =IF(G21="No major surgery",0,G21) -> 0 | J21: =PROPER(H21) -> Yes | K21: =PROPER(D21) -> No | L21: =IF(B21<18.5,"Underweight",IF(B21<25,"Normal Weight",IF(B21<30,"Overweight","Obesity"))) -> Obesity | M21: =IF(C21<5.7,"Normal",IF(C21<6.5,"Prediabetes","Diabetes")) -> Diabetes
A22: Id21 | B22: 36.3 | C22: 11.5 | D22: yes | E22: No | F22: No | G22: 2 | H22: yes | I22: =IF(G22="No major surgery",0,G22) -> 2 | J22: =PROPER(H22) -> Yes | K22: =PROPER(D22) -> Yes | L22: =IF(B22<18.5,"Underweight",IF(B22<25,"Normal Weight",IF(B22<30,"Overweight","Obesity"))) -> Obesity | M22: =IF(C22<5.7,"Normal",IF(C22<6.5,"Prediabetes","Diabetes")) -> Diabetes
A23: Id22 | B23: 32.2 | C23: 6.22 | D23: yes | E23: No | F23: No | G23: 2 | H23: yes | I23: =IF(G23="No major surgery",0,G23) -> 2 | J23: =PROPER(H23) -> Yes | K23: =PROPER(D23) -> Yes | L23: =IF(B23<18.5,"Underweight",IF(B23<25,"Normal Weight",IF(B23<30,"Overweight","Obesity"))) -> Obesity | M23: =IF(C23<5.7,"Normal",IF(C23<6.5,"Prediabetes","Diabetes")) -> Prediabetes
A24: Id23 | B24: 31.3 | C24: 11.38 | D24: No | E24: No | F24: No | G24: 3 | H24: yes | I24: =IF(G24="No major surgery",0,G24) -> 3 | J24: =PROPER(H24) -> Yes | K24: =PROPER(D24) -> No | L24: =IF(B24<18.5,"Underweight",IF(B24<25,"Normal Weight",IF(B24<30,"Overweight","Obesity"))) -> Obesity | M24: =IF(C24<5.7,"Normal",IF(C24<6.5,"Prediabetes","Diabetes")) -> Diabetes
A25: Id24 | B25: 41.8 | C25: 7.89 | D25: yes | E25: No | F25: No | G25: 2 | H25: yes | I25: =IF(G25="No major surgery",0,G25) -> 2 | J25: =PROPER(H25) -> Yes | K25: =PROPER(D25) -> Yes | L25: =IF(B25<18.5,"Underweight",IF(B25<25,"Normal Weight",IF(B25<30,"Overweight","Obesity"))) -> Obesity | M25: =IF(C25<5.7,"Normal",IF(C25<6.5,"Prediabetes","Diabetes")) -> Diabetes
A26: Id25 | B26: 35.09 | C26: 4.38 | D26: yes | E26: No | F26: No | G26: 2 | H26: yes | I26: =IF(G26="No major surgery",0,G26) -> 2 | J26: =PROPER(H26) -> Yes | K26: =PROPER(D26) -> Yes | L26: =IF(B26<18.5,"Underweight",IF(B26<25,"Normal Weight",IF(B26<30,"Overweight","Obesity"))) -> Obesity | M26: =IF(C26<5.7,"Normal",IF(C26<6.5,"Prediabetes","Diabetes")) -> Normal
A27: Id26 | B27: 33.88 | C27: 7.01 | D27: No | E27: No | F27: No | G27: 3 | H27: yes | I27: =IF(G27="No major surgery",0,G27) -> 3 | J27: =PROPER(H27) -> Yes | K27: =PROPER(D27) -> No | L27: =IF(B27<18.5,"Underweight",IF(B27<25,"Normal Weight",IF(B27<30,"Overweight","Obesity"))) -> Obesity | M27: =IF(C27<5.7,"Normal",IF(C27<6.5,"Prediabetes","Diabetes")) -> Diabetes
A28: Id27 | B28: 30.875 | C28: 11.88 | D28: No | E28: No | F28: No | G28: No major surgery | H28: yes | I28: =IF(G28="No major surgery",0,G28) -> 0 | J28: =PROPER(H28) -> Yes | K28: =PROPER(D28) -> No | L28: =IF(B28<18.5,"Underweight",IF(B28<25,"Normal Weight",IF(B28<30,"Overweight","Obesity"))) -> Obesity | M28: =IF(C28<5.7,"Normal",IF(C28<6.5,"Prediabetes","Diabetes")) -> Diabetes
A29: Id28 | B29: 36.86 | C29: 5.19 | D29: yes | E29: No | F29: Yes | G29: 1 | H29: yes | I29: =IF(G29="No major surgery",0,G29) -> 1 | J29: =PROPER(H29) -> Yes | K29: =PROPER(D29) -> Yes | L29: =IF(B29<18.5,"Underweight",IF(B29<25,"Normal Weight",IF(B29<30,"Overweight","Obesity"))) -> Obesity | M29: =IF(C29<5.7,"Normal",IF(C29<6.5,"Prediabetes","Diabetes")) -> Normal
A30: Id29 | B30: 35.86 | C30: 6.74 | D30: yes | E30: No | F30: No | G30: 2 | H30: yes | I30: =IF(G30="No major surgery",0,G30) -> 2 | J30: =PROPER(H30) -> Yes | K30: =PROPER(D30) -> Yes | L30: =IF(B30<18.5,"Underweight",IF(B30<25,"Normal Weight",IF(B30<30,"Overweight","Obesity"))) -> Obesity | M30: =IF(C30<5.7,"Normal",IF(C30<6.5,"Prediabetes","Diabetes")) -> Diabetes
A31: Id30 | B31: 37.05 | C31: 8.44 | D31: No | E31: No | F31: No | G31: No major surgery | H31: yes | I31: =IF(G31="No major surgery",0,G31) -> 0 | J31: =PROPER(H31) -> Yes | K31: =PROPER(D31) -> No | L31: =IF(B31<18.5,"Underweight",IF(B31<25,"Normal Weight",IF(B31<30,"Overweight","Obesity"))) -> Obesity | M31: =IF(C31<5.7,"Normal",IF(C31<6.5,"Prediabetes","Diabetes")) -> Diabetes
A32: Id31 | B32: 43.89 | C32: 8.71 | D32: No | E32: No | F32: No | G32: No major surgery | H32: yes | I32: =IF(G32="No major surgery",0,G32) -> 0 | J32: =PROPER(H32) -> Yes | K32: =PROPER(D32) -> No | L32: =IF(B32<18.5,"Underweight",IF(B32<25,"Normal Weight",IF(B32<30,"Overweight","Obesity"))) -> Obesity | M32: =IF(C32<5.7,"Normal",IF(C32<6.5,"Prediabetes","Diabetes")) -> Diabetes
A33: Id32 | B33: 42.35 | C33: 5.08 | D33: yes | E33: No | F33: No | G33: No major surgery | H33: yes | I33: =IF(G33="No major surgery",0,G33) -> 0 | J33: =PROPER(H33) -> Yes | K33: =PROPER(D33) -> Yes | L33: =IF(B33<18.5,"Underweight",IF(B33<25,"Normal Weight",IF(B33<30,"Overweight","Obesity"))) -> Obesity | M33: =IF(C33<5.7,"Normal",IF(C33<6.5,"Prediabetes","Diabetes")) -> Normal
A34: Id33 | B34: 31.35 | C34: 6.86 | D34: No | E34: No | F34: No | G34: No major surgery | H34: yes | I34: =IF(G34="No major surgery",0,G34) -> 0 | J34: =PROPER(H34) -> Yes | K34: =PROPER(D34) -> No | L34: =IF(B34<18.5,"Underweight",IF(B34<25,"Normal Weight",IF(B34<30,"Overweight","Obesity"))) -> Obesity | M34: =IF(C34<5.7,"Normal",IF(C34<6.5,"Prediabetes","Diabetes")) -> Diabetes
A35: Id34 | B35: 47.6 | C35: 5.95 | D35: yes | E35: No | F35: No | G35: No major surgery | H35: yes | I35: =IF(G35="No major surgery",0,G35) -> 0 | J35: =PROPER(H35) -> Yes | K35: =PROPER(D35) -> Yes | L35: =IF(B35<18.5,"Underweight",IF(B35<25,"Normal Weight",IF(B35<30,"Overweight","Obesity"))) -> Obesity | M35: =IF(C35<5.7,"Normal",IF(C35<6.5,"Prediabetes","Diabetes")) -> Prediabetes
A36: Id35 | B36: 46.2 | C36: 6.09 | D36: No | E36: No | F36: Yes | G36: 1 | H36: yes | I36: =IF(G36="No major surgery",0,G36) -> 1 | J36: =PROPER(H36) -> Yes | K36: =PROPER(D36) -> No | L36: =IF(B36<18.5,"Underweight",IF(B36<25,"Normal Weight",IF(B36<30,"Overweight","Obesity"))) -> Obesity | M36: =IF(C36<5.7,"Normal",IF(C36<6.5,"Prediabetes","Diabetes")) -> Prediabetes
A37: Id36 | B37: 32.015 | C37: 11.75 | D37: No | E37: No | F37: No | G37: No major surgery | H37: yes | I37: =IF(G37="No major surgery",0,G37) -> 0 | J37: =PROPER(H37) -> Yes | K37: =PROPER(D37) -> No | L37: =IF(B37<18.5,"Underweight",IF(B37<25,"Normal Weight",IF(B37<30,"Overweight","Obesity"))) -> Obesity | M37: =IF(C37<5.7,"Normal",IF(C37<6.5,"Prediabetes","Diabetes")) -> Diabetes
A38: Id37 | B38: 40.565 | C38: 7.37 | D38: No | E38: No | F38: No | G38: No major surgery | H38: yes | I38: =IF(G38="No major surgery",0,G38) -> 0 | J38: =PROPER(H38) -> Yes | K38: =PROPER(D38) -> No | L38: =IF(B38<18.5,"Underweight",IF(B38<25,"Normal Weight",IF(B38<30,"Overweight","Obesity"))) -> Obesity | M38: =IF(C38<5.7,"Normal",IF(C38<6.5,"Prediabetes","Diabetes")) -> Diabetes
A39: Id38 | B39: 32.45 | C39: 11.91 | D39: No | E39: No | F39: No | G39: No major surgery | H39: yes | I39: =IF(G39="No major surgery",0,G39) -> 0 | J39: =PROPER(H39) -> Yes | K39: =PROPER(D39) -> No | L39: =IF(B39<18.5,"Underweight",IF(B39<25,"Normal Weight",IF(B39<30,"Overweight","Obesity"))) -> Obesity | M39: =IF(C39<5.7,"Normal",IF(C39<6.5,"Prediabetes","Diabetes")) -> Diabetes
A40: Id39 | B40: 34.96 | C40: 6.52 | D40: No | E40: No | F40: No | G40: No major surgery | H40: yes | I40: =IF(G40="No major surgery",0,G40) -> 0 | J40: =PROPER(H40) -> Yes | K40: =PROPER(D40) -> No | L40: =IF(B40<18.5,"Underweight",IF(B40<25,"Normal Weight",IF(B40<30,"Overweight","Obesity"))) -> Obesity | M40: =IF(C40<5.7,"Normal",IF(C40<6.5,"Prediabetes","Diabetes")) -> Diabetes
...

Sheet Hospitalisation Details
A1: Customer ID | B1: year | C1: month | D1: date | E1: children | F1: charges | G1: Hospital tier | H1: City tier | I1: State ID | J1: Year (Cleaned) | K1: Month (Cleaned) | L1: Hospital Tier (Cleaned) | M1: City Tier ( Cleaned) | N1: State ID (Cleaned) | O1: Date of Birth | P1: Age
A2: Id2335 | B2: 1992 | C2: Jul | D2: 9 | E2: 0 | F2: 563.84 | G2: tier - 2 | H2: tier - 3 | I2: R1013 | J2: 1992 | K2: Jul | L2: tier - 2 | M2: tier - 3 | N2: R1013 | O2: =IF(A2="?","",DATE(J2,MATCH(K2,{"Jan","Feb","Mar","Apr","May","Jun","Jul","Aug","Sep","Oct","Nov","Dec"},0),D2)) -> 33794 | P2: =IF(O2="","",DATEDIF(O2,DATE(2023,6,8),"Y")) -> 30 | S2: Data Cleaning Helper Calculations
A3: Id2334 | B3: 1992 | C3: Nov | D3: 30 | E3: 0 | F3: 570.62 | G3: tier - 2 | H3: tier - 1 | I3: R1013 | J3: 1992 | K3: Nov | L3: tier - 2 | M3: tier - 1 | N3: R1013 | O3: =IF(A3="?","",DATE(J3,MATCH(K3,{"Jan","Feb","Mar","Apr","May","Jun","Jul","Aug","Sep","Oct","Nov","Dec"},0),D3)) -> 33938 | P3: =IF(O3="","",DATEDIF(O3,DATE(2023,6,8),"Y")) -> 30 | S3: Average Year | T3: =AVERAGE(B2:B2344) -> 1982.8415
A4: Id2333 | B4: 1993 | C4: Jun | D4: 30 | E4: 0 | F4: 600 | G4: tier - 2 | H4: tier - 1 | I4: R1013 | J4: 1993 | K4: Jun | L4: tier - 2 | M4: tier - 1 | N4: R1013 | O4: =IF(A4="?","",DATE(J4,MATCH(K4,{"Jan","Feb","Mar","Apr","May","Jun","Jul","Aug","Sep","Oct","Nov","Dec"},0),D4)) -> 34150 | P4: =IF(O4="","",DATEDIF(O4,DATE(2023,6,8),"Y")) -> 29 | S4: Rounded Year | T4: =ROUNDUP(T3,0) -> 1983
A5: Id2332 | B5: 1992 | C5: Sep | D5: 13 | E5: 0 | F5: 604.54 | G5: tier - 3 | H5: tier - 3 | I5: R1013 | J5: 1992 | K5: Sep | L5: tier - 3 | M5: tier - 3 | N5: R1013 | O5: =IF(A5="?","",DATE(J5,MATCH(K5,{"Jan","Feb","Mar","Apr","May","Jun","Jul","Aug","Sep","Oct","Nov","Dec"},0),D5)) -> 33860 | P5: =IF(O5="","",DATEDIF(O5,DATE(2023,6,8),"Y")) -> 30 | S5: Hospital tier = "tier - 1" count | T5: =COUNTIF(G2:G2344,"tier - 1") -> 309
A6: Id2331 | B6: 1998 | C6: Jul | D6: 27 | E6: 0 | F6: 637.26 | G6: tier - 3 | H6: tier - 3 | I6: R1013 | J6: 1998 | K6: Jul | L6: tier - 3 | M6: tier - 3 | N6: R1013 | O6: =IF(A6="?","",DATE(J6,MATCH(K6,{"Jan","Feb","Mar","Apr","May","Jun","Jul","Aug","Sep","Oct","Nov","Dec"},0),D6)) -> 36003 | P6: =IF(O6="","",DATEDIF(O6,DATE(2023,6,8),"Y")) -> 24 | S6: Hospital tier = "tier - 2" count | T6: =COUNTIF(G2:G2344,"tier - 2") -> 1339
A7: Id2330 | B7: 2001 | C7: Nov | D7: 20 | E7: 0 | F7: 646.14 | G7: tier - 3 | H7: tier - 3 | I7: R1012 | J7: 2001 | K7: Nov | L7: tier - 3 | M7: tier - 3 | N7: R1012 | O7: =IF(A7="?","",DATE(J7,MATCH(K7,{"Jan","Feb","Mar","Apr","May","Jun","Jul","Aug","Sep","Oct","Nov","Dec"},0),D7)) -> 37215 | P7: =IF(O7="","",DATEDIF(O7,DATE(2023,6,8),"Y")) -> 21 | S7: Hospital tier = "tier - 3" count | T7: =COUNTIF(G2:G2344,"tier - 3") -> 694
A8: Id2329 | B8: 1993 | C8: Jun | D8: 1 | E8: 0 | F8: 650 | G8: tier - 3 | H8: tier - 3 | I8: R1013 | J8: 1993 | K8: Jun | L8: tier - 3 | M8: tier - 3 | N8: R1013 | O8: =IF(A8="?","",DATE(J8,MATCH(K8,{"Jan","Feb","Mar","Apr","May","Jun","Jul","Aug","Sep","Oct","Nov","Dec"},0),D8)) -> 34121 | P8: =IF(O8="","",DATEDIF(O8,DATE(2023,6,8),"Y")) -> 30 | S8: Hospital tier Mode (for filling "?") | T8: =IF(AND(T5>=T6,T5>=T7),"tier - 1",IF(T6>=T7,"tier - 2","tier - 3")) -> tier - 2
A9: Id2328 | B9: 1995 | C9: Jul | D9: 4 | E9: 0 | F9: 650 | G9: tier - 3 | H9: tier - 3 | I9: R1013 | J9: 1995 | K9: Jul | L9: tier - 3 | M9: tier - 3 | N9: R1013 | O9: =IF(A9="?","",DATE(J9,MATCH(K9,{"Jan","Feb","Mar","Apr","May","Jun","Jul","Aug","Sep","Oct","Nov","Dec"},0),D9)) -> 34884 | P9: =IF(O9="","",DATEDIF(O9,DATE(2023,6,8),"Y")) -> 27 | S9: City tier = "tier - 1" count | T9: =COUNTIF(H2:H2344,"tier - 1") -> 734
A10: Id2327 | B10: 2002 | C10: Nov | D10: 29 | E10: 0 | F10: 668 | G10: tier - 3 | H10: tier - 2 | I10: R1012 | J10: 2002 | K10: Nov | L10: tier - 3 | M10: tier - 2 | N10: R1012 | O10: =IF(A10="?","",DATE(J10,MATCH(K10,{"Jan","Feb","Mar","Apr","May","Jun","Jul","Aug","Sep","Oct","Nov","Dec"},0),D10)) -> 37589 | P10: =IF(O10="","",DATEDIF(O10,DATE(2023,6,8),"Y")) -> 20 | S10: City tier = "tier - 2" count | T10: =COUNTIF(H2:H2344,"tier - 2") -> 812
A11: Id2326 | B11: 1997 | C11: Nov | D11: 9 | E11: 0 | F11: 670 | G11: tier - 3 | H11: tier - 3 | I11: R1013 | J11: 1997 | K11: Nov | L11: tier - 3 | M11: tier - 3 | N11: R1013 | O11: =IF(A11="?","",DATE(J11,MATCH(K11,{"Jan","Feb","Mar","Apr","May","Jun","Jul","Aug","Sep","Oct","Nov","Dec"},0),D11)) -> 35743 | P11: =IF(O11="","",DATEDIF(O11,DATE(2023,6,8),"Y")) -> 25 | S11: City tier = "tier - 3" count | T11: =COUNTIF(H2:H2344,"tier - 3") -> 796
A12: Id2325 | B12: 2001 | C12: Sep | D12: 12 | E12: 0 | F12: 687.54 | G12: tier - 3 | H12: tier - 2 | I12: R1013 | J12: 2001 | K12: Sep | L12: tier - 3 | M12: tier - 2 | N12: R1013 | O12: =IF(A12="?","",DATE(J12,MATCH(K12,{"Jan","Feb","Mar","Apr","May","Jun","Jul","Aug","Sep","Oct","Nov","Dec"},0),D12)) -> 37146 | P12: =IF(O12="","",DATEDIF(O12,DATE(2023,6,8),"Y")) -> 21 | S12: City tier Mode (for filling "?") | T12: =IF(AND(T9>=T10,T9>=T11),"tier - 1",IF(T10>=T11,"tier - 2","tier - 3")) -> tier - 2
A13: Id2324 | B13: 1999 | C13: Dec | D13: 26 | E13: 0 | F13: 700 | G13: ? | H13: tier - 3 | I13: R1013 | J13: 1999 | K13: Dec | L13: tier - 2 | M13: tier - 3 | N13: R1013 | O13: =IF(A13="?","",DATE(J13,MATCH(K13,{"Jan","Feb","Mar","Apr","May","Jun","Jul","Aug","Sep","Oct","Nov","Dec"},0),D13)) -> 36520 | P13: =IF(O13="","",DATEDIF(O13,DATE(2023,6,8),"Y")) -> 23
A14: Id2323 | B14: 1999 | C14: Dec | D14: 14 | E14: 0 | F14: 722.99 | G14: tier - 3 | H14: tier - 1 | I14: R1013 | J14: 1999 | K14: Dec | L14: tier - 3 | M14: tier - 1 | N14: R1013 | O14: =IF(A14="?","",DATE(J14,MATCH(K14,{"Jan","Feb","Mar","Apr","May","Jun","Jul","Aug","Sep","Oct","Nov","Dec"},0),D14)) -> 36508 | P14: =IF(O14="","",DATEDIF(O14,DATE(2023,6,8),"Y")) -> 23
A15: Id2322 | B15: 2002 | C15: ? | D15: 19 | E15: 0 | F15: 750 | G15: tier - 3 | H15: tier - 1 | I15: R1012 | J15: 2002 | K15: Sep | L15: tier - 3 | M15: tier - 1 | N15: R1012 | O15: =IF(A15="?","",DATE(J15,MATCH(K15,{"Jan","Feb","Mar","Apr","May","Jun","Jul","Aug","Sep","Oct","Nov","Dec"},0),D15)) -> 37518 | P15: =IF(O15="","",DATEDIF(O15,DATE(2023,6,8),"Y")) -> 20
A16: Id2321 | B16: 1993 | C16: Aug | D16: 9 | E16: 0 | F16: 760 | G16: tier - 3 | H16: tier - 1 | I16: R1013 | J16: 1993 | K16: Aug | L16: tier - 3 | M16: tier - 1 | N16: R1013 | O16: =IF(A16="?","",DATE(J16,MATCH(K16,{"Jan","Feb","Mar","Apr","May","Jun","Jul","Aug","Sep","Oct","Nov","Dec"},0),D16)) -> 34190 | P16: =IF(O16="","",DATEDIF(O16,DATE(2023,6,8),"Y")) -> 29
A17: Id2320 | B17: 1996 | C17: Oct | D17: 22 | E17: 0 | F17: 760 | G17: tier - 3 | H17: tier - 3 | I17: R1013 | J17: 1996 | K17: Oct | L17: tier - 3 | M17: tier - 3 | N17: R1013 | O17: =IF(A17="?","",DATE(J17,MATCH(K17,{"Jan","Feb","Mar","Apr","May","Jun","Jul","Aug","Sep","Oct","Nov","Dec"},0),D17)) -> 35360 | P17: =IF(O17="","",DATEDIF(O17,DATE(2023,6,8),"Y")) -> 26
A18: Id2319 | B18: 1993 | C18: Jun | D18: 28 | E18: 0 | F18: 770 | G18: tier - 3 | H18: tier - 3 | I18: R1013 | J18: 1993 | K18: Jun | L18: tier - 3 | M18: tier - 3 | N18: R1013 | O18: =IF(A18="?","",DATE(J18,MATCH(K18,{"Jan","Feb","Mar","Apr","May","Jun","Jul","Aug","Sep","Oct","Nov","Dec"},0),D18)) -> 34148 | P18: =IF(O18="","",DATEDIF(O18,DATE(2023,6,8),"Y")) -> 29
A19: Id2318 | B19: 1996 | C19: ? | D19: 18 | E19: 0 | F19: 770.38 | G19: tier - 3 | H19: ? | I19: R1012 | J19: 1996 | K19: Sep | L19: tier - 3 | M19: tier - 2 | N19: R1012 | O19: =IF(A19="?","",DATE(J19,MATCH(K19,{"Jan","Feb","Mar","Apr","May","Jun","Jul","Aug","Sep","Oct","Nov","Dec"},0),D19)) -> 35326 | P19: =IF(O19="","",DATEDIF(O19,DATE(2023,6,8),"Y")) -> 26
A20: Id2317 | B20: 1995 | C20: Dec | D20: 7 | E20: 0 | F20: 773.54 | G20: tier - 3 | H20: tier - 2 | I20: R1013 | J20: 1995 | K20: Dec | L20: tier - 3 | M20: tier - 2 | N20: R1013 | O20: =IF(A20="?","",DATE(J20,MATCH(K20,{"Jan","Feb","Mar","Apr","May","Jun","Jul","Aug","Sep","Oct","Nov","Dec"},0),D20)) -> 35040 | P20: =IF(O20="","",DATEDIF(O20,DATE(2023,6,8),"Y")) -> 27
A21: Id2316 | B21: 2004 | C21: Oct | D21: 7 | E21: 0 | F21: 830.52 | G21: tier - 3 | H21: tier - 2 | I21: R1011 | J21: 2004 | K21: Oct | L21: tier - 3 | M21: tier - 2 | N21: R1011 | O21: =IF(A21="?","",DATE(J21,MATCH(K21,{"Jan","Feb","Mar","Apr","May","Jun","Jul","Aug","Sep","Oct","Nov","Dec"},0),D21)) -> 38267 | P21: =IF(O21="","",DATEDIF(O21,DATE(2023,6,8),"Y")) -> 18
A22: Id2315 | B22: 2000 | C22: Nov | D22: 18 | E22: 0 | F22: 865.41 | G22: tier - 3 | H22: tier - 1 | I22: R1013 | J22: 2000 | K22: Nov | L22: tier - 3 | M22: tier - 1 | N22: R1013 | O22: =IF(A22="?","",DATE(J22,MATCH(K22,{"Jan","Feb","Mar","Apr","May","Jun","Jul","Aug","Sep","Oct","Nov","Dec"},0),D22)) -> 36848 | P22: =IF(O22="","",DATEDIF(O22,DATE(2023,6,8),"Y")) -> 22
A23: Id2314 | B23: 1993 | C23: Nov | D23: 27 | E23: 0 | F23: 896.21 | G23: tier - 3 | H23: tier - 1 | I23: R1013 | J23: 1993 | K23: Nov | L23: tier - 3 | M23: tier - 1 | N23: R1013 | O23: =IF(A23="?","",DATE(J23,MATCH(K23,{"Jan","Feb","Mar","Apr","May","Jun","Jul","Aug","Sep","Oct","Nov","Dec"},0),D23)) -> 34300 | P23: =IF(O23="","",DATEDIF(O23,DATE(2023,6,8),"Y")) -> 29
A24: Id2313 | B24: 1994 | C24: Oct | D24: 30 | E24: 0 | F24: 915.07 | G24: tier - 3 | H24: tier - 1 | I24: R1013 | J24: 1994 | K24: Oct | L24: tier - 3 | M24: tier - 1 | N24: R1013 | O24: =IF(A24="?","",DATE(J24,MATCH(K24,{"Jan","Feb","Mar","Apr","May","Jun","Jul","Aug","Sep","Oct","Nov","Dec"},0),D24)) -> 34637 | P24: =IF(O24="","",DATEDIF(O24,DATE(2023,6,8),"Y")) -> 28
... A1050: Id1290 | B1050: 1977 | C1050: Jul | D1050: 26 | E1050: 2 | F1050: 8527.53 | G1050: tier - 2 | H1050: tier - 2 | I1050: R1013 | J1050: 1977 | K1050: Jul | L1050: tier - 2 | M1050: tier - 2 | N1050: R1013 | O1050: =IF(A1050="?","",DATE(J1050,MATCH(K1050,{"Jan","Feb","Mar","Apr","May","Jun","Jul","Aug","Sep","Oct","Nov","Dec"},0),D1050)) -> 28332 | P1050: =IF(O1050="","",DATEDIF(O1050,DATE(2023,6,8),"Y")) -> 45
A1051: Id1289 | B1051: ? | C1051: Jul | D1051: 24 | E1051: 0 | F1051: 8534.67 | G1051: tier - 2 | H1051: tier - 3 | I1051: R1024 | J1051: 1983 | K1051: Jul | L1051: tier - 2 | M1051: tier - 3 | N1051: R1024 | O1051: =IF(A1051="?","",DATE(J1051,MATCH(K1051,{"Jan","Feb","Mar","Apr","May","Jun","Jul","Aug","Sep","Oct","Nov","Dec"},0),D1051)) -> 30521 | P1051: =IF(O1051="","",DATEDIF(O1051,DATE(2023,6,8),"Y")) -> 39
A1052: Id1288 | B1052: 1981 | C1052: Dec | D1052: 27 | E1052: 3 | F1052: 8538.29 | G1052: tier - 2 | H1052: tier - 3 | I1052: R1024 | J1052: 1981 | K1052: Dec | L1052: tier - 2 | M1052: tier - 3 | N1052: R1024 | O1052: =IF(A1052="?","",DATE(J1052,MATCH(K1052,{"Jan","Feb","Mar","Apr","May","Jun","Jul","Aug","Sep","Oct","Nov","Dec"},0),D1052)) -> 29947 | P1052: =IF(O1052="","",DATEDIF(O1052,DATE(2023,6,8),"Y")) -> 41
A1053: Id1287 | B1053: 1975 | C1053: Nov | D1053: 6 | E1053: 1 | F1053: 8539.67 | G1053: tier - 2 | H1053: tier - 3 | I1053: R1011 | J1053: 1975 | K1053: Nov | L1053: tier - 2 | M1053: tier - 3 | N1053: R1011 | O1053: =IF(A1053="?","",DATE(J1053,MATCH(K1053,{"Jan","Feb","Mar","Apr","May","Jun","Jul","Aug","Sep","Oct","Nov","Dec"},0),D1053)) -> 27704 | P1053: =IF(O1053="","",DATEDIF(O1053,DATE(2023,6,8),"Y")) -> 47
A1054: Id1286 | B1054: ? | C1054: Dec | D1054: 12 | E1054: 1 | F1054: 8547.69 | G1054: tier - 2 | H1054: tier - 1 | I1054: R1013 | J1054: 1983 | K1054: Dec | L1054: tier - 2 | M1054: tier - 1 | N1054: R1013 | O1054: =IF(A1054="?","",DATE(J1054,MATCH(K1054,{"Jan","Feb","Mar","Apr","May","Jun","Jul","Aug","Sep","Oct","Nov","Dec"},0),D1054)) -> 30662 | P1054: =IF(O1054="","",DATEDIF(O1054,DATE(2023,6,8),"Y")) -> 39
A1055: Id1285 | B1055: 1975 | C1055: Aug | D1055: 6 | E1055: 1 | F1055: 8551.35 | G1055: tier - 2 | H1055: tier - 2 | I1055: R1011 | J1055: 1975 | K1055: Aug | L1055: tier - 2 | M1055: tier - 2 | N1055: R1011 | O1055: =IF(A1055="?","",DATE(J1055,MATCH(K1055,{"Jan","Feb","Mar","Apr","May","Jun","Jul","Aug","Sep","Oct","Nov","Dec"},0),D1055)) -> 27612 | P1055: =IF(O1055="","",DATEDIF(O1055,DATE(2023,6,8),"Y")) -> 47
A1056: Id1284 | B1056: 1975 | C1056: Aug | D1056: 21 | E1056: 1 | F1056: 8556.91 | G1056: tier - 2 | H1056: tier - 1 | I1056: R1011 | J1056: 1975 | K1056: Aug | L1056: tier - 2 | M1056: tier - 1 | N1056: R1011 | O1056: =IF(A1056="?","",DATE(J1056,MATCH(K1056,{"Jan","Feb","Mar","Apr","May","Jun","Jul","Aug","Sep","Oct","Nov","Dec"},0),D1056)) -> 27627 | P1056: =IF(O1056="","",DATEDIF(O1056,DATE(2023,6,8),"Y")) -> 47
A1057: Id1283 | B1057: 1988 | C1057: Sep | D1057: 21 | E1057: 3 | F1057: 8567.25 | G1057: tier - 2 | H1057: tier - 1 | I1057: R1012 | J1057: 1988 | K1057: Sep | L1057: tier - 2 | M1057: tier - 1 | N1057: R1012 | O1057: =IF(A1057="?","",DATE(J1057,MATCH(K1057,{"Jan","Feb","Mar","Apr","May","Jun","Jul","Aug","Sep","Oct","Nov","Dec"},0),D1057)) -> 32407 | P1057: =IF(O1057="","",DATEDIF(O1057,DATE(2023,6,8),"Y")) -> 34
A1058: Id1282 | B1058: 1975 | C1058: Sep | D1058: 26 | E1058: 1 | F1058: 8569.86 | G1058: tier - 2 | H1058: tier - 3 | I1058: R1013 | J1058: 1975 | K1058: Sep | L1058: tier - 2 | M1058: tier - 3 | N1058: R1013 | O1058: =IF(A1058="?","",DATE(J1058,MATCH(K1058,{"Jan","Feb","Mar","Apr","May","Jun","Jul","Aug","Sep","Oct","Nov","Dec"},0),D1058)) -> 27663 | P1058: =IF(O1058="","",DATEDIF(O1058,DATE(2023,6,8),"Y")) -> 47
A1059: Id1281 | B1059: 1982 | C1059: Dec | D1059: 6 | E1059: 3 | F1059: 8572.04 | G1059: tier - 2 | H1059: tier - 2 | I1059: R1021 | J1059: 1982 | K1059: Dec | L1059: tier - 2 | M1059: tier - 2 | N1059: R1021 | O1059: =IF(A1059="?","",DATE(J1059,MATCH(K1059,{"Jan","Feb","Mar","Apr","May","Jun","Jul","Aug","Sep","Oct","Nov","Dec"},0),D1059)) -> 30291 | P1059: =IF(O1059="","",DATEDIF(O1059,DATE(2023,6,8),"Y")) -> 40
A1060: Id1280 | B1060: 1987 | C1060: Nov | D1060: 11 | E1060: 3 | F1060: 8573.3 | G1060: tier - 2 | H1060: tier - 2 | I1060: R1021 | J1060: 1987 | K1060: Nov | L1060: tier - 2 | M1060: tier - 2 | N1060: R1021 | O1060: =IF(A1060="?","",DATE(J1060,MATCH(K1060,{"Jan","Feb","Mar","Apr","May","Jun","Jul","Aug","Sep","Oct","Nov","Dec"},0),D1060)) -> 32092 | P1060: =IF(O1060="","",DATEDIF(O1060,DATE(2023,6,8),"Y")) -> 35
A1061: Id1279 | B1061: 1983 | C1061: Dec | D1061: 30 | E1061: 5 | F1061: 8582.3 | G1061: tier - 2 | H1061: tier - 1 | I1061: R1013 | J1061: 1983 | K1061: Dec | L1061: tier - 2 | M1061: tier - 1 | N1061: R1013 | O1061: =IF(A1061="?","",DATE(J1061,MATCH(K1061,{"Jan","Feb","Mar","Apr","May","Jun","Jul","Aug","Sep","Oct","Nov","Dec"},0),D1061)) -> 30680 | P1061: =IF(O1061="","",DATEDIF(O1061,DATE(2023,6,8),"Y")) -> 39
A1062: Id1278 | B1062: 1983 | C1062: Jul | D1062: 25 | E1062: 5 | F1062: 8596.83 | G1062: tier - 2 | H1062: tier - 3 | I1062: R1013 | J1062: 1983 | K1062: Jul | L1062: tier - 2 | M1062: tier - 3 | N1062: R1013 | O1062: =IF(A1062="?","",DATE(J1062,MATCH(K1062,{"Jan","Feb","Mar","Apr","May","Jun","Jul","Aug","Sep","Oct","Nov","Dec"},0),D1062)) -> 30522 | P1062: =IF(O1062="","",DATEDIF(O1062,DATE(2023,6,8),"Y")) -> 39
A1063: Id1277 | B1063: 1973 | C1063: Jul | D1063: 11 | E1063: 0 | F1063: 8601.33 | G1063: tier - 2 | H1063: tier - 1 | I1063: R1013 | J1063: 1973 | K1063: Jul | L1063: tier - 2 | M1063: tier - 1 | N1063: R1013 | O1063: =IF(A1063="?","",DATE(J1063,MATCH(K1063,{"Jan","Feb","Mar","Apr","May","Jun","Jul","Aug","Sep","Oct","Nov","Dec"},0),D1063)) -> 26856 | P1063: =IF(O1063="","",DATEDIF(O1063,DATE(2023,6,8),"Y")) -> 49
A1064: Id1276 | B1064: 1977 | C1064: Sep | D1064: 24 | E1064: 2 | F1064: 8603.82 | G1064: tier - 2 | H1064: tier - 1 | I1064: R1019 | J1064: 1977 | K1064: Sep | L1064: tier - 2 | M1064: tier - 1 | N1064: R1019 | O1064: =IF(A1064="?","",DATE(J1064,MATCH(K1064,{"Jan","Feb","Mar","Apr","May","Jun","Jul","Aug","Sep","Oct","Nov","Dec"},0),D1064)) -> 28392 | P1064: =IF(O1064="","",DATEDIF(O1064,DATE(2023,6,8),"Y")) -> 45
A1065: Id1275 | B1065: 1977 | C1065: Nov | D1065: 12 | E1065: 2 | F1065: 8604.48 | G1065: tier - 3 | H1065: tier - 2 | I1065: R1016 | J1065: 1977 | K1065: Nov | L1065: tier - 3 | M1065: tier - 2 | N1065: R1016 | O1065: =IF(A1065="?","",DATE(J1065,MATCH(K1065,{"Jan","Feb","Mar","Apr","May","Jun","Jul","Aug","Sep","Oct","Nov","Dec"},0),D1065)) -> 28441 | P1065: =IF(O1065="","",DATEDIF(O1065,DATE(2023,6,8),"Y")) -> 45
...

Sheet Healthcare
A1: Customer ID | B1: Title | C1: First Name | D1: Last Name | E1: BMI | F1: HBA1C | G1: Heart Issues | H1: Any Transplants | I1: Cancer history | J1: Number Of Major Surgeries | K1: Smoker | L1: Weight Status | M1: Diabetes Status | N1: Date of Birth | O1: charges | P1: Hospital tier | Q1: City tier | R1: State ID | S1: Age
A2: ='Medical Examinations'!A2 -> Id1 | B2: =VLOOKUP($A2,'Customer Names'!A:E,3,FALSE) -> Ms. | C2: =VLOOKUP($A2,'Customer Names'!A:E,4,FALSE) -> Kelly | D2: =VLOOKUP($A2,'Customer Names'!A:E,5,FALSE) -> Hawks | E2: =VLOOKUP($A2,'Medical Examinations'!$A:$H,2,FALSE) -> 47.41 | F2: =VLOOKUP($A2,'Medical Examinations'!$A:$H,3,FALSE) -> 7.47 | G2: =VLOOKUP($A2,'Medical Examinations'!$A:$N,11,0) -> No | H2: =VLOOKUP($A2,'Medical Examinations'!$A:$N,5,0) -> No | I2: =VLOOKUP($A2,'Medical Examinations'!$A:$N,6,0) -> No | J2: =VLOOKUP($A2,'Medical Examinations'!$A:$N,9,0) -> 0 | K2: =VLOOKUP($A2,'Medical Examinations'!$A:$N,10,0) -> Yes | L2: =VLOOKUP($A2,'Medical Examinations'!$A:$N,12,0) -> Obesity | M2: =VLOOKUP($A2,'Medical Examinations'!$A:$N,13,0) -> Diabetes | N2: =IFERROR(VLOOKUP($A2,'Hospitalisation Details'!$A:$P,15,0),"") -> 25123 | O2: =IFERROR(VLOOKUP($A2,'Hospitalisation Details'!$A:$P,6,0),"") -> 63770.43 | P2: =IFERROR(VLOOKUP($A2,'Hospitalisation Details'!$A:$P,12,0),"") -> tier - 1 | Q2: =IFERROR(VLOOKUP($A2,'Hospitalisation Details'!$A:$P,13,0),"") -> tier - 3 | R2: =IFERROR(VLOOKUP($A2,'Hospitalisation Details'!$A:$P,14,0),"") -> R1013 | S2: =IFERROR(VLOOKUP($A2,'Hospitalisation Details'!$A:$P,16,0),"") -> 54
A3: ='Medical Examinations'!A3 -> Id2 | B3: =VLOOKUP($A3,'Customer Names'!A:E,3,FALSE) -> Mr. | C3: =VLOOKUP($A3,'Customer Names'!$A:$E,4,FALSE) -> Matthew D | D3: =VLOOKUP($A3,'Customer Names'!A:E,5,FALSE) -> Lehner | E3: =VLOOKUP($A3,'Medical Examinations'!$A:$H,2,FALSE) -> 30.36 | F3: =VLOOKUP($A3,'Medical Examinations'!$A:$H,3,FALSE) -> 5.77 | G3: =VLOOKUP($A3,'Medical Examinations'!$A:$N,11,0) -> No | H3: =VLOOKUP($A3,'Medical Examinations'!$A:$N,5,0) -> No | I3: =VLOOKUP($A3,'Medical Examinations'!$A:$N,6,0) -> No | J3: =VLOOKUP($A3,'Medical Examinations'!$A:$N,9,0) -> 0 | K3: =VLOOKUP($A3,'Medical Examinations'!$A:$N,10,0) -> Yes | L3: =VLOOKUP($A3,'Medical Examinations'!$A:$N,12,0) -> Obesity | M3: =VLOOKUP($A3,'Medical Examinations'!$A:$N,13,0) -> Prediabetes | N3: =IFERROR(VLOOKUP($A3,'Hospitalisation Details'!$A:$P,15,0),"") -> 28284 | O3: =IFERROR(VLOOKUP($A3,'Hospitalisation Details'!$A:$P,6,0),"") -> 62592.87 | P3: =IFERROR(VLOOKUP($A3,'Hospitalisation Details'!$A:$P,12,0),"") -> tier - 2 | Q3: =IFERROR(VLOOKUP($A3,'Hospitalisation Details'!$A:$P,13,0),"") -> tier - 3 | R3: =IFERROR(VLOOKUP($A3,'Hospitalisation Details'!$A:$P,14,0),"") -> R1013 | S3: =IFERROR(VLOOKUP($A3,'Hospitalisation Details'!$A:$P,16,0),"") -> 46 | U3: Note
A4: ='Medical Examinations'!A4 -> Id3 | B4: =VLOOKUP($A4,'Customer Names'!A:E,3,FALSE) -> Mr. | C4: =VLOOKUP($A4,'Customer Names'!$A:$E,4,FALSE) -> Phil | D4: =VLOOKUP($A4,'Customer Names'!A:E,5,FALSE) -> Lu | E4: =VLOOKUP($A4,'Medical Examinations'!$A:$H,2,FALSE) -> 34.485 | F4: =VLOOKUP($A4,'Medical Examinations'!$A:$H,3,FALSE) -> 11.87 | G4: =VLOOKUP($A4,'Medical Examinations'!$A:$N,11,0) -> Yes | H4: =VLOOKUP($A4,'Medical Examinations'!$A:$N,5,0) -> No | I4: =VLOOKUP($A4,'Medical Examinations'!$A:$N,6,0) -> No | J4: =VLOOKUP($A4,'Medical Examinations'!$A:$N,9,0) -> 2 | K4: =VLOOKUP($A4,'Medical Examinations'!$A:$N,10,0) -> Yes | L4: =VLOOKUP($A4,'Medical Examinations'!$A:$N,12,0) -> Obesity | M4: =VLOOKUP($A4,'Medical Examinations'!$A:$N,13,0) -> Diabetes | N4: =IFERROR(VLOOKUP($A4,'Hospitalisation Details'!$A:$P,15,0),"") -> 25822 | O4: =IFERROR(VLOOKUP($A4,'Hospitalisation Details'!$A:$P,6,0),"") -> 60021.4 | P4: =IFERROR(VLOOKUP($A4,'Hospitalisation Details'!$A:$P,12,0),"") -> tier - 1 | Q4: =IFERROR(VLOOKUP($A4,'Hospitalisation Details'!$A:$P,13,0),"") -> tier - 1 | R4: =IFERROR(VLOOKUP($A4,'Hospitalisation Details'!$A:$P,14,0),"") -> R1012 | S4: =IFERROR(VLOOKUP($A4,'Hospitalisation Details'!$A:$P,16,0),"") -> 52
A5: ='Medical Examinations'!A5 -> Id4 | B5: =VLOOKUP($A5,'Customer Names'!A:E,3,FALSE) -> Ms. | C5: =VLOOKUP($A5,'Customer Names'!$A:$E,4,FALSE) -> Kelsey | D5: =VLOOKUP($A5,'Customer Names'!A:E,5,FALSE) -> Osborne | E5: =VLOOKUP($A5,'Medical Examinations'!$A:$H,2,FALSE) -> 38.095 | F5: =VLOOKUP($A5,'Medical Examinations'!$A:$H,3,FALSE) -> 6.05 | G5: =VLOOKUP($A5,'Medical Examinations'!$A:$N,11,0) -> No | H5: =VLOOKUP($A5,'Medical Examinations'!$A:$N,5,0) -> No | I5: =VLOOKUP($A5,'Medical Examinations'!$A:$N,6,0) -> No | J5: =VLOOKUP($A5,'Medical Examinations'!$A:$N,9,0) -> 0 | K5: =VLOOKUP($A5,'Medical Examinations'!$A:$N,10,0) -> Yes | L5: =VLOOKUP($A5,'Medical Examinations'!$A:$N,12,0) -> Obesity | M5: =VLOOKUP($A5,'Medical Examinations'!$A:$N,13,0) -> Prediabetes | N5: =IFERROR(VLOOKUP($A5,'Hospitalisation Details'!$A:$P,15,0),"") -> 33395 | O5: =IFERROR(VLOOKUP($A5,'Hospitalisation Details'!$A:$P,6,0),"") -> 58571.07 | P5: =IFERROR(VLOOKUP($A5,'Hospitalisation Details'!$A:$P,12,0),"") -> tier - 1 | Q5: =IFERROR(VLOOKUP($A5,'Hospitalisation Details'!$A:$P,13,0),"") -> tier - 3 | R5: =IFERROR(VLOOKUP($A5,'Hospitalisation Details'!$A:$P,14,0),"") -> R1024 | S5: =IFERROR(VLOOKUP($A5,'Hospitalisation Details'!$A:$P,16,0),"") -> 32 | U5: Blue in color is indicates table Customer Name
A6: ='Medical Examinations'!A6 -> Id5 | B6: =VLOOKUP($A6,'Customer Names'!A:E,3,FALSE) -> Ms. | C6: =VLOOKUP($A6,'Customer Names'!$A:$E,4,FALSE) -> Kristyn | D6: =VLOOKUP($A6,'Customer Names'!A:E,5,FALSE) -> Kadala | E6: =VLOOKUP($A6,'Medical Examinations'!$A:$H,2,FALSE) -> 35.53 | F6: =VLOOKUP($A6,'Medical Examinations'!$A:$H,3,FALSE) -> 5.45 | G6: =VLOOKUP($A6,'Medical Examinations'!$A:$N,11,0) -> No | H6: =VLOOKUP($A6,'Medical Examinations'!$A:$N,5,0) -> No | I6: =VLOOKUP($A6,'Medical Examinations'!$A:$N,6,0) -> No | J6: =VLOOKUP($A6,'Medical Examinations'!$A:$N,9,0) -> 0 | K6: =VLOOKUP($A6,'Medical Examinations'!$A:$N,10,0) -> Yes | L6: =VLOOKUP($A6,'Medical Examinations'!$A:$N,12,0) -> Obesity | M6: =VLOOKUP($A6,'Medical Examinations'!$A:$N,13,0) -> Normal | N6: =IFERROR(VLOOKUP($A6,'Hospitalisation Details'!$A:$P,15,0),"") -> 32678 | O6: =IFERROR(VLOOKUP($A6,'Hospitalisation Details'!$A:$P,6,0),"") -> 55135.4 | P6: =IFERROR(VLOOKUP($A6,'Hospitalisation Details'!$A:$P,12,0),"") -> tier - 1 | Q6: =IFERROR(VLOOKUP($A6,'Hospitalisation Details'!$A:$P,13,0),"") -> tier - 2 | R6: =IFERROR(VLOOKUP($A6,'Hospitalisation Details'!$A:$P,14,0),"") -> R1012 | S6: =IFERROR(VLOOKUP($A6,'Hospitalisation Details'!$A:$P,16,0),"") -> 33
A7: ='Medical Examinations'!A7 -> Id6 | B7: =VLOOKUP($A7,'Customer Names'!A:E,3,FALSE) -> Mr. | C7: =VLOOKUP($A7,'Customer Names'!$A:$E,4,FALSE) -> Russell B. | D7: =VLOOKUP($A7,'Customer Names'!A:E,5,FALSE) -> Baker | E7: =VLOOKUP($A7,'Medical Examinations'!$A:$H,2,FALSE) -> 32.8 | F7: =VLOOKUP($A7,'Medical Examinations'!$A:$H,3,FALSE) -> 6.59 | G7: =VLOOKUP($A7,'Medical Examinations'!$A:$N,11,0) -> No | H7: =VLOOKUP($A7,'Medical Examinations'!$A:$N,5,0) -> No | I7: =VLOOKUP($A7,'Medical Examinations'!$A:$N,6,0) -> No | J7: =VLOOKUP($A7,'Medical Examinations'!$A:$N,9,0) -> 0 | K7: =VLOOKUP($A7,'Medical Examinations'!$A:$N,10,0) -> Yes | L7: =VLOOKUP($A7,'Medical Examinations'!$A:$N,12,0) -> Obesity | M7: =VLOOKUP($A7,'Medical Examinations'!$A:$N,13,0) -> Diabetes | N7: =IFERROR(VLOOKUP($A7,'Hospitalisation Details'!$A:$P,15,0),"") -> 22862 | O7: =IFERROR(VLOOKUP($A7,'Hospitalisation Details'!$A:$P,6,0),"") -> 52590.83 | P7: =IFERROR(VLOOKUP($A7,'Hospitalisation Details'!$A:$P,12,0),"") -> tier - 1 | Q7: =IFERROR(VLOOKUP($A7,'Hospitalisation Details'!$A:$P,13,0),"") -> tier - 3 | R7: =IFERROR(VLOOKUP($A7,'Hospitalisation Details'!$A:$P,14,0),"") -> R1011 | S7: =IFERROR(VLOOKUP($A7,'Hospitalisation Details'!$A:$P,16,0),"") -> 60 | U7: Orange in color indicates Medical Examination table
A8: ='Medical Examinations'!A8 -> Id7 | B8: =VLOOKUP($A8,'Customer Names'!A:E,3,FALSE) -> Mr. | C8: =VLOOKUP($A8,'Customer Names'!$A:$E,4,FALSE) -> Scott | D8: =VLOOKUP($A8,'Customer Names'!A:E,5,FALSE) -> Macpherson | E8: =VLOOKUP($A8,'Medical Examinations'!$A:$H,2,FALSE) -> 36.4 | F8: =VLOOKUP($A8,'Medical Examinations'!$A:$H,3,FALSE) -> 6.07 | G8: =VLOOKUP($A8,'Medical Examinations'!$A:$N,11,0) -> No | H8: =VLOOKUP($A8,'Medical Examinations'!$A:$N,5,0) -> No | I8: =VLOOKUP($A8,'Medical Examinations'!$A:$N,6,0) -> No | J8: =VLOOKUP($A8,'Medical Examinations'!$A:$N,9,0) -> 0 | K8: =VLOOKUP($A8,'Medical Examinations'!$A:$N,10,0) -> Yes | L8: =VLOOKUP($A8,'Medical Examinations'!$A:$N,12,0) -> Obesity | M8: =VLOOKUP($A8,'Medical Examinations'!$A:$N,13,0) -> Prediabetes | N8: =IFERROR(VLOOKUP($A8,'Hospitalisation Details'!$A:$P,15,0),"") -> 34634 | O8: =IFERROR(VLOOKUP($A8,'Hospitalisation Details'!$A:$P,6,0),"") -> 51194.56 | P8: =IFERROR(VLOOKUP($A8,'Hospitalisation Details'!$A:$P,12,0),"") -> tier - 1 | Q8: =IFERROR(VLOOKUP($A8,'Hospitalisation Details'!$A:$P,13,0),"") -> tier - 3 | R8: =IFERROR(VLOOKUP($A8,'Hospitalisation Details'!$A:$P,14,0),"") -> R1011 | S8: =IFERROR(VLOOKUP($A8,'Hospitalisation Details'!$A:$P,16,0),"") -> 28
A9: ='Medical Examinations'!A9 -> Id8 | B9: =VLOOKUP($A9,'Customer Names'!A:E,3,FALSE) -> Mr. | C9: =VLOOKUP($A9,'Customer Names'!$A:$E,4,FALSE) -> Stephen | D9: =VLOOKUP($A9,'Customer Names'!A:E,5,FALSE) -> Hallman | E9: =VLOOKUP($A9,'Medical Examinations'!$A:$H,2,FALSE) -> 36.96 | F9: =VLOOKUP($A9,'Medical Examinations'!$A:$H,3,FALSE) -> 7.93 | G9: =VLOOKUP($A9,'Medical Examinations'!$A:$N,11,0) -> No | H9: =VLOOKUP($A9,'Medical Examinations'!$A:$N,5,0) -> No | I9: =VLOOKUP($A9,'Medical Examinations'!$A:$N,6,0) -> No | J9: =VLOOKUP($A9,'Medical Examinations'!$A:$N,9,0) -> 3 | K9: =VLOOKUP($A9,'Medical Examinations'!$A:$N,10,0) -> Yes | L9: =VLOOKUP($A9,'Medical Examinations'!$A:$N,12,0) -> Obesity | M9: =VLOOKUP($A9,'Medical Examinations'!$A:$N,13,0) -> Diabetes | N9: =IFERROR(VLOOKUP($A9,'Hospitalisation Details'!$A:$P,15,0),"") -> 21363 | O9: =IFERROR(VLOOKUP($A9,'Hospitalisation Details'!$A:$P,6,0),"") -> 49577.66 | P9: =IFERROR(VLOOKUP($A9,'Hospitalisation Details'!$A:$P,12,0),"") -> tier - 2 | Q9: =IFERROR(VLOOKUP($A9,'Hospitalisation Details'!$A:$P,13,0),"") -> tier - 2 | R9: =IFERROR(VLOOKUP($A9,'Hospitalisation Details'!$A:$P,14,0),"") -> R1013 | S9: =IFERROR(VLOOKUP($A9,'Hospitalisation Details'!$A:$P,16,0),"") -> 64 | U9: Green in color indicates Hospitalisation Details table
A10: ='Medical Examinations'!A10 -> Id9 | B10: =VLOOKUP($A10,'Customer Names'!A:E,3,FALSE) -> Mr. | C10: =VLOOKUP($A10,'Customer Names'!$A:$E,4,FALSE) -> Patrick R. | D10: =VLOOKUP($A10,'Customer Names'!A:E,5,FALSE) -> Moran | E10: =VLOOKUP($A10,'Medical Examinations'!$A:$H,2,FALSE) -> 41.14 | F10: =VLOOKUP($A10,'Medical Examinations'!$A:$H,3,FALSE) -> 9.58 | G10: =VLOOKUP($A10,'Medical Examinations'!$A:$N,11,0) -> Yes | H10: =VLOOKUP($A10,'Medical Examinations'!$A:$N,5,0) -> No | I10: =VLOOKUP($A10,'Medical Examinations'!$A:$N,6,0) -> Yes | J10: =VLOOKUP($A10,'Medical Examinations'!$A:$N,9,0) -> 1 | K10: =VLOOKUP($A10,'Medical Examinations'!$A:$N,10,0) -> Yes | L10: =VLOOKUP($A10,'Medical Examinations'!$A:$N,12,0) -> Obesity | M10: =VLOOKUP($A10,'Medical Examinations'!$A:$N,13,0) -> Diabetes | N10: =IFERROR(VLOOKUP($A10,'Hospitalisation Details'!$A:$P,15,0),"") -> 23258 | O10: =IFERROR(VLOOKUP($A10,'Hospitalisation Details'!$A:$P,6,0),"") -> 48970.25 | P10: =IFERROR(VLOOKUP($A10,'Hospitalisation Details'!$A:$P,12,0),"") -> tier - 1 | Q10: =IFERROR(VLOOKUP($A10,'Hospitalisation Details'!$A:$P,13,0),"") -> tier - 2 | R10: =IFERROR(VLOOKUP($A10,'Hospitalisation Details'!$A:$P,14,0),"") -> R1013 | S10: =IFERROR(VLOOKUP($A10,'Hospitalisation Details'!$A:$P,16,0),"") -> 59
A11: ='Medical Examinations'!A11 -> Id10 | B11: =VLOOKUP($A11,'Customer Names'!A:E,3,FALSE) -> Ms. | C11: =VLOOKUP($A11,'Customer Names'!$A:$E,4,FALSE) -> Brooke N. | D11: =VLOOKUP($A11,'Customer Names'!A:E,5,FALSE) -> Benner | E11: =VLOOKUP($A11,'Medical Examinations'!$A:$H,2,FALSE) -> 38.06 | F11: =VLOOKUP($A11,'Medical Examinations'!$A:$H,3,FALSE) -> 10.79 | G11: =VLOOKUP($A11,'Medical Examinations'!$A:$N,11,0) -> No | H11: =VLOOKUP($A11,'Medical Examinations'!$A:$N,5,0) -> No | I11: =VLOOKUP($A11,'Medical Examinations'!$A:$N,6,0) -> No | J11: =VLOOKUP($A11,'Medical Examinations'!$A:$N,9,0) -> 0 | K11: =VLOOKUP($A11,'Medical Examinations'!$A:$N,10,0) -> Yes | L11: =VLOOKUP($A11,'Medical Examinations'!$A:$N,12,0) -> Obesity | M11: =VLOOKUP($A11,'Medical Examinations'!$A:$N,13,0) -> Diabetes | N11: =IFERROR(VLOOKUP($A11,'Hospitalisation Details'!$A:$P,15,0),"") -> 28853 | O11: =IFERROR(VLOOKUP($A11,'Hospitalisation Details'!$A:$P,6,0),"") -> 48885.14 | P11: =IFERROR(VLOOKUP($A11,'Hospitalisation Details'!$A:$P,12,0),"") -> tier - 1 | Q11: =IFERROR(VLOOKUP($A11,'Hospitalisation Details'!$A:$P,13,0),"") -> tier - 2 | R11: =IFERROR(VLOOKUP($A11,'Hospitalisation Details'!$A:$P,14,0),"") -> R1013 | S11: =IFERROR(VLOOKUP($A11,'Hospitalisation Details'!$A:$P,16,0),"") -> 44
A12: ='Medical Examinations'!A12 -> Id11 | B12: =VLOOKUP($A12,'Customer Names'!A:E,3,FALSE) -> Ms. | C12: =VLOOKUP($A12,'Customer Names'!$A:$E,4,FALSE) -> Paola Andrea | D12: =VLOOKUP($A12,'Customer Names'!A:E,5,FALSE) -> Fierro Vargas | E12: =VLOOKUP($A12,'Medical Examinations'!$A:$H,2,FALSE) -> 37.7 | F12: =VLOOKUP($A12,'Medical Examinations'!$A:$H,3,FALSE) -> 5.96 | G12: =VLOOKUP($A12,'Medical Examinations'!$A:$N,11,0) -> Yes | H12: =VLOOKUP($A12,'Medical Examinations'!$A:$N,5,0) -> No | I12: =VLOOKUP($A12,'Medical Examinations'!$A:$N,6,0) -> No | J12: =VLOOKUP($A12,'Medical Examinations'!$A:$N,9,0) -> 2 | K12: =VLOOKUP($A12,'Medical Examinations'!$A:$N,10,0) -> Yes | L12: =VLOOKUP($A12,'Medical Examinations'!$A:$N,12,0) -> Obesity | M12: =VLOOKUP($A12,'Medical Examinations'!$A:$N,13,0) -> Prediabetes | N12: =IFERROR(VLOOKUP($A12,'Hospitalisation Details'!$A:$P,15,0),"") -> 21753 | O12: =IFERROR(VLOOKUP($A12,'Hospitalisation Details'!$A:$P,6,0),"") -> 48824.45 | P12: =IFERROR(VLOOKUP($A12,'Hospitalisation Details'!$A:$P,12,0),"") -> tier - 2 | Q12: =IFERROR(VLOOKUP($A12,'Hospitalisation Details'!$A:$P,13,0),"") -> tier - 1 | R12: =IFERROR(VLOOKUP($A12,'Hospitalisation Details'!$A:$P,14,0),"") -> R1011 | S12: =IFERROR(VLOOKUP($A12,'Hospitalisation Details'!$A:$P,16,0),"") -> 63
A13: ='Medical Examinations'!A13 -> Id12 | B13: =VLOOKUP($A13,'Customer Names'!A:E,3,FALSE) -> Mr. | C13: =VLOOKUP($A13,'Customer Names'!$A:$E,4,FALSE) -> David | D13: =VLOOKUP($A13,'Customer Names'!A:E,5,FALSE) -> Franz | E13: =VLOOKUP($A13,'Medical Examinations'!$A:$H,2,FALSE) -> 42.13 | F13: =VLOOKUP($A13,'Medical Examinations'!$A:$H,3,FALSE) -> 11.9 | G13: =VLOOKUP($A13,'Medical Examinations'!$A:$N,11,0) -> No | H13: =VLOOKUP($A13,'Medical Examinations'!$A:$N,5,0) -> No | I13: =VLOOKUP($A13,'Medical Examinations'!$A:$N,6,0) -> No | J13: =VLOOKUP($A13,'Medical Examinations'!$A:$N,9,0) -> 0 | K13: =VLOOKUP($A13,'Medical Examinations'!$A:$N,10,0) -> Yes | L13: =VLOOKUP($A13,'Medical Examinations'!$A:$N,12,0) -> Obesity | M13: =VLOOKUP($A13,'Medical Examinations'!$A:$N,13,0) -> Diabetes | N13: =IFERROR(VLOOKUP($A13,'Hospitalisation Details'!$A:$P,15,0),"") -> 24042 | O13: =IFERROR(VLOOKUP($A13,'Hospitalisation Details'!$A:$P,6,0),"") -> 48675.52 | P13: =IFERROR(VLOOKUP($A13,'Hospitalisation Details'!$A:$P,12,0),"") -> tier - 1 | Q13: =IFERROR(VLOOKUP($A13,'Hospitalisation Details'!$A:$P,13,0),"") -> tier - 2 | R13: =IFERROR(VLOOKUP($A13,'Hospitalisation Details'!$A:$P,14,0),"") -> R1013 | S13: =IFERROR(VLOOKUP($A13,'Hospitalisation Details'!$A:$P,16,0),"") -> 57
A14: ='Medical Examinations'!A14 -> Id13 | B14: =VLOOKUP($A14,'Customer Names'!A:E,3,FALSE) -> Mr. | C14: =VLOOKUP($A14,'Customer Names'!$A:$E,4,FALSE) -> Wade | D14: =VLOOKUP($A14,'Customer Names'!A:E,5,FALSE) -> Foster | E14: =VLOOKUP($A14,'Medical Examinations'!$A:$H,2,FALSE) -> 40.92 | F14: =VLOOKUP($A14,'Medical Examinations'!$A:$H,3,FALSE) -> 8.41 | G14: =VLOOKUP($A14,'Medical Examinations'!$A:$N,11,0) -> No | H14: =VLOOKUP($A14,'Medical Examinations'!$A:$N,5,0) -> No | I14: =VLOOKUP($A14,'Medical Examinations'!$A:$N,6,0) -> No | J14: =VLOOKUP($A14,'Medical Examinations'!$A:$N,9,0) -> 0 | K14: =VLOOKUP($A14,'Medical Examinations'!$A:$N,10,0) -> Yes | L14: =VLOOKUP($A14,'Medical Examinations'!$A:$N,12,0) -> Obesity | M14: =VLOOKUP($A14,'Medical Examinations'!$A:$N,13,0) -> Diabetes | N14: =IFERROR(VLOOKUP($A14,'Hospitalisation Details'!$A:$P,15,0),"") -> 22930 | O14: =IFERROR(VLOOKUP($A14,'Hospitalisation Details'!$A:$P,6,0),"") -> 48673.56 | P14: =IFERROR(VLOOKUP($A14,'Hospitalisation Details'!$A:$P,12,0),"") -> tier - 1 | Q14: =IFERROR(VLOOKUP($A14,'Hospitalisation Details'!$A:$P,13,0),"") -> tier - 2 | R14: =IFERROR(VLOOKUP($A14,'Hospitalisation Details'!$A:$P,14,0),"") -> R1013 | S14: =IFERROR(VLOOKUP($A14,'Hospitalisation Details'!$A:$P,16,0),"") -> 60
A15: ='Medical Examinations'!A15 -> Id14 | B15: =VLOOKUP($A15,'Customer Names'!A:E,3,FALSE) -> Mr. | C15: =VLOOKUP($A15,'Customer Names'!$A:$E,4,FALSE) -> Franklin | D15: =VLOOKUP($A15,'Customer Names'!A:E,5,FALSE) -> Tenorio | E15: =VLOOKUP($A15,'Medical Examinations'!$A:$H,2,FALSE) -> 40.565 | F15: =VLOOKUP($A15,'Medical Examinations'!$A:$H,3,FALSE) -> 7.02 | G15: =VLOOKUP($A15,'Medical Examinations'!$A:$N,11,0) -> No | H15: =VLOOKUP($A15,'Medical Examinations'!$A:$N,5,0) -> No | I15: =VLOOKUP($A15,'Medical Examinations'!$A:$N,6,0) -> No | J15: =VLOOKUP($A15,'Medical Examinations'!$A:$N,9,0) -> 0 | K15: =VLOOKUP($A15,'Medical Examinations'!$A:$N,10,0) -> Yes | L15: =VLOOKUP($A15,'Medical Examinations'!$A:$N,12,0) -> Obesity | M15: =VLOOKUP($A15,'Medical Examinations'!$A:$N,13,0) -> Diabetes | N15: =IFERROR(VLOOKUP($A15,'Hospitalisation Details'!$A:$P,15,0),"") -> 25173 | O15: =IFERROR(VLOOKUP($A15,'Hospitalisation Details'!$A:$P,6,0),"") -> 48549.18 | P15: =IFERROR(VLOOKUP($A15,'Hospitalisation Details'!$A:$P,12,0),"") -> tier - 1 | Q15: =IFERROR(VLOOKUP($A15,'Hospitalisation Details'!$A:$P,13,0),"") -> tier - 3 | R15: =IFERROR(VLOOKUP($A15,'Hospitalisation Details'!$A:$P,14,0),"") -> R1016 | S15: =IFERROR(VLOOKUP($A15,'Hospitalisation Details'!$A:$P,16,0),"") -> 54
A16: ='Medical Examinations'!A16 -> Id15 | B16: =VLOOKUP($A16,'Customer Names'!A:E,3,FALSE) -> Ms. | C16: =VLOOKUP($A16,'Customer Names'!$A:$E,4,FALSE) -> Leilani M. | D16: =VLOOKUP($A16,'Customer Names'!A:E,5,FALSE) -> Rios | E16: =VLOOKUP($A16,'Medical Examinations'!$A:$H,2,FALSE) -> 36.385 | F16: =VLOOKUP($A16,'Medical Examinations'!$A:$H,3,FALSE) -> 7.59 | G16: =VLOOKUP($A16,'Medical Examinations'!$A:$N,11,0) -> Yes | H16: =VLOOKUP($A16,'Medical Examinations'!$A:$N,5,0) -> No | I16: =VLOOKUP($A16,'Medical Examinations'!$A:$N,6,0) -> No | J16: =VLOOKUP($A16,'Medical Examinations'!$A:$N,9,0) -> 2 | K16: =VLOOKUP($A16,'Medical Examinations'!$A:$N,10,0) -> Yes | L16: =VLOOKUP($A16,'Medical Examinations'!$A:$N,12,0) -> Obesity | M16: =VLOOKUP($A16,'Medical Examinations'!$A:$N,13,0) -> Diabetes | N16: =IFERROR(VLOOKUP($A16,'Hospitalisation Details'!$A:$P,15,0),"") -> 22636 | O16: =IFERROR(VLOOKUP($A16,'Hospitalisation Details'!$A:$P,6,0),"") -> 48517.56 | P16: =IFERROR(VLOOKUP($A16,'Hospitalisation Details'!$A:$P,12,0),"") -> tier - 1 | Q16: =IFERROR(VLOOKUP($A16,'Hospitalisation Details'!$A:$P,13,0),"") -> tier - 3 | R16: =IFERROR(VLOOKUP($A16,'Hospitalisation Details'!$A:$P,14,0),"") -> R1024 | S16: =IFERROR(VLOOKUP($A16,'Hospitalisation Details'!$A:$P,16,0),"") -> 61
A17: ='Medical Examinations'!A17 -> Id16 | B17: =VLOOKUP($A17,'Customer Names'!A:E,3,FALSE) -> Mr. | C17: =VLOOKUP($A17,'Customer Names'!$A:$E,4,FALSE) -> Philippe | D17: =VLOOKUP($A17,'Customer Names'!A:E,5,FALSE) -> Viau-Dupuis | E17: =VLOOKUP($A17,'Medical Examinations'!$A:$H,2,FALSE) -> 39.9 | F17: =VLOOKUP($A17,'Medical Examinations'!$A:$H,3,FALSE) -> 11.32 | G17: =VLOOKUP($A17,'Medical Examinations'!$A:$N,11,0) -> No | H17: =VLOOKUP($A17,'Medical Examinations'!$A:$N,5,0) -> No | I17: =VLOOKUP($A17,'Medical Examinations'!$A:$N,6,0) -> No | J17: =VLOOKUP($A17,'Medical Examinations'!$A:$N,9,0) -> 0 | K17: =VLOOKUP($A17,'Medical Examinations'!$A:$N,10,0) -> Yes | L17: =VLOOKUP($A17,'Medical Examinations'!$A:$N,12,0) -> Obesity | M17: =VLOOKUP($A17,'Medical Examinations'!$A:$N,13,0) -> Diabetes | N17: =IFERROR(VLOOKUP($A17,'Hospitalisation Details'!$A:$P,15,0),"") -> 22885 | O17: =IFERROR(VLOOKUP($A17,'Hospitalisation Details'!$A:$P,6,0),"") -> 48173.36 | P17: =IFERROR(VLOOKUP($A17,'Hospitalisation Details'!$A:$P,12,0),"") -> tier - 1 | Q17: =IFERROR(VLOOKUP($A17,'Hospitalisation Details'!$A:$P,13,0),"") -> tier - 3 | R17: =IFERROR(VLOOKUP($A17,'Hospitalisation Details'!$A:$P,14,0),"") -> R1011 | S17: =IFERROR(VLOOKUP($A17,'Hospitalisation Details'!$A:$P,16,0),"") -> 60
A18: ='Medical Examinations'!A18 -> Id17 | B18: =VLOOKUP($A18,'Customer Names'!A:E,3,FALSE) -> Ms. | C18: =VLOOKUP($A18,'Customer Names'!$A:$E,4,FALSE) -> Jennifer A. | D18: =VLOOKUP($A18,'Customer Names'!A:E,5,FALSE) -> Cronin | E18: =VLOOKUP($A18,'Medical Examinations'!$A:$H,2,FALSE) -> 33.8 | F18: =VLOOKUP($A18,'Medical Examinations'!$A:$H,3,FALSE) -> 7.67 | G18: =VLOOKUP($A18,'Medical Examinations'!$A:$N,11,0) -> No | H18: =VLOOKUP($A18,'Medical Examinations'!$A:$N,5,0) -> No | I18: =VLOOKUP($A18,'Medical Examinations'!$A:$N,6,0) -> No | J18: =VLOOKUP($A18,'Medical Examinations'!$A:$N,9,0) -> 3 | K18: =VLOOKUP($A18,'Medical Examinations'!$A:$N,10,0) -> Yes | L18: =VLOOKUP($A18,'Medical Examinations'!$A:$N,12,0) -> Obesity | M18: =VLOOKUP($A18,'Medical Examinations'!$A:$N,13,0) -> Diabetes | N18: =IFERROR(VLOOKUP($A18,'Hospitalisation Details'!$A:$P,15,0),"") -> 21505 | O18: =IFERROR(VLOOKUP($A18,'Hospitalisation Details'!$A:$P,6,0),"") -> 47928.03 | P18: =IFERROR(VLOOKUP($A18,'Hospitalisation Details'!$A:$P,12,0),"") -> tier - 2 | Q18: =IFERROR(VLOOKUP($A18,'Hospitalisation Details'!$A:$P,13,0),"") -> tier - 3 | R18: =IFERROR(VLOOKUP($A18,'Hospitalisation Details'!$A:$P,14,0),"") -> R1011 | S18: =IFERROR(VLOOKUP($A18,'Hospitalisation Details'!$A:$P,16,0),"") -> 64
A19: ='Medical Examinations'!A19 -> Id18 | B19: =VLOOKUP($A19,'Customer Names'!A:E,3,FALSE) -> Ms. | C19: =VLOOKUP($A19,'Customer Names'!$A:$E,4,FALSE) -> Christina M. | D19: =VLOOKUP($A19,'Customer Names'!A:E,5,FALSE) -> Noordstar | E19: =VLOOKUP($A19,'Medical Examinations'!$A:$H,2,FALSE) -> 36.765 | F19: =VLOOKUP($A19,'Medical Examinations'!$A:$H,3,FALSE) -> 7.29 | G19: =VLOOKUP($A19,'Medical Examinations'!$A:$N,11,0) -> Yes | H19: =VLOOKUP($A19,'Medical Examinations'!$A:$N,5,0) -> No | I19: =VLOOKUP($A19,'Medical Examinations'!$A:$N,6,0) -> Yes | J19: =VLOOKUP($A19,'Medical Examinations'!$A:$N,9,0) -> 1 | K19: =VLOOKUP($A19,'Medical Examinations'!$A:$N,10,0) -> Yes | L19: =VLOOKUP($A19,'Medical Examinations'!$A:$N,12,0) -> Obesity | M19: =VLOOKUP($A19,'Medical Examinations'!$A:$N,13,0) -> Diabetes | N19: =IFERROR(VLOOKUP($A19,'Hospitalisation Details'!$A:$P,15,0),"") -> 23228 | O19: =IFERROR(VLOOKUP($A19,'Hospitalisation Details'!$A:$P,6,0),"") -> 47896.79 | P19: =IFERROR(VLOOKUP($A19,'Hospitalisation Details'!$A:$P,12,0),"") -> tier - 1 | Q19: =IFERROR(VLOOKUP($A19,'Hospitalisation Details'!$A:$P,13,0),"") -> tier - 3 | R19: =IFERROR(VLOOKUP($A19,'Hospitalisation Details'!$A:$P,14,0),"") -> R1024 | S19: =IFERROR(VLOOKUP($A19,'Hospitalisation Details'!$A:$P,16,0),"") -> 59
A20: ='Medical Examinations'!A20 -> Id19 | B20: =VLOOKUP($A20,'Customer Names'!A:E,3,FALSE) -> Mr. | C20: =VLOOKUP($A20,'Customer Names'!$A:$E,4,FALSE) -> Said Sr. | D20: =VLOOKUP($A20,'Customer Names'!A:E,5,FALSE) -> Boudalia | E20: =VLOOKUP($A20,'Medical Examinations'!$A:$H,2,FALSE) -> 36.955 | F20: =VLOOKUP($A20,'Medical Examinations'!$A:$H,3,FALSE) -> 4.72 | G20: =VLOOKUP($A20,'Medical Examinations'!$A:$N,11,0) -> Yes | H20: =VLOOKUP($A20,'Medical Examinations'!$A:$N,5,0) -> No | I20: =VLOOKUP($A20,'Medical Examinations'!$A:$N,6,0) -> No | J20: =VLOOKUP($A20,'Medical Examinations'!$A:$N,9,0) -> 1 | K20: =VLOOKUP($A20,'Medical Examinations'!$A:$N,10,0) -> Yes | L20: =VLOOKUP($A20,'Medical Examinations'!$A:$N,12,0) -> Obesity | M20: =VLOOKUP($A20,'Medical Examinations'!$A:$N,13,0) -> Normal | N20: =IFERROR(VLOOKUP($A20,'Hospitalisation Details'!$A:$P,15,0),"") -> 23688 | O20: =IFERROR(VLOOKUP($A20,'Hospitalisation Details'!$A:$P,6,0),"") -> 47496.49 | P20: =IFERROR(VLOOKUP($A20,'Hospitalisation Details'!$A:$P,12,0),"") -> tier - 1 | Q20: =IFERROR(VLOOKUP($A20,'Hospitalisation Details'!$A:$P,13,0),"") -> tier - 3 | R20: =IFERROR(VLOOKUP($A20,'Hospitalisation Details'!$A:$P,14,0),"") -> R1012 | S20: =IFERROR(VLOOKUP($A20,'Hospitalisation Details'!$A:$P,16,0),"") -> 58
